Workbook

Sheet XtEHR
A1: Code | B1: XtEHR Class | H1: | | I1: XtEHR | J1: | | K1: FHIR R4 | L1: | | M1: KOS | N1: | | Q1: DICOM | R1: DICOM SR
H2: | | I2: ----------- | J2: | | K2: ----------- | L2: | | M2: ----------- | N2: |
A3: EHDSImagingStudy1 | B3: EHDSImagingStudy | D3: 0..* | H3: | | I3: =B3&IF(LEN(TRIM(C3))>0,"-","")&C3 -> EHDSImagingStudy | J3: | | K3: =IF(LEN(A3)>0,_xlfn.IFNA(_xlfn.XLOOKUP(A3,FHIR!M:M,FHIR!C:C),""),"") | L3: | | M3: =IF(LEN(TRIM(Q3))>0,Q3,R3) | N3: | | R3: =IF(LEN(A3)>0,_xlfn.IFNA(_xlfn.XLOOKUP(A3,'KOS SR'!X:X,'KOS SR'!N:N),""),"")
A4: EHDSImagingStudy2 | B4: EHDSImagingStudy | C4: header | D4: 1..1 | E4: Base | F4: =SUBSTITUTE(E4," http://www.xt-ehr.eu/fhir/models/StructureDefinition/", "" ) -> Base | H4: | | I4: =B4&IF(LEN(TRIM(C4))>0,"-","")&C4 -> EHDSImagingStudy-header | J4: | | K4: =IF(LEN(A4)>0,_xlfn.IFNA(_xlfn.XLOOKUP(A4,FHIR!M:M,FHIR!E:E),""),"") | L4: | | M4: =IF(LEN(TRIM(Q4))>0,Q4,R4) | N4: | | R4: =IF(LEN(A4)>0,_xlfn.IFNA(_xlfn.XLOOKUP(A4,'KOS SR'!X:X,'KOS SR'!N:N),""),"")
A5: EHDSImagingStudy3 | B5: EHDSImagingStudy | C5: header.subject | D5: 1..1 | E5: http://www.xt-ehr.eu/fhir/models/StructureDefinition/EHDSPatient | F5: =SUBSTITUTE(E5," http://www.xt-ehr.eu/fhir/models/StructureDefinition/", "" ) -> EHDSPatient | H5: | | I5: =B5&IF(LEN(TRIM(C5))>0,"-","")&C5 -> EHDSImagingStudy-header.subject | J5: | | K5: =IF(LEN(A5)>0,_xlfn.IFNA(_xlfn.XLOOKUP(A5,FHIR!M:M,FHIR!E:E),""),"") -> ImagingStudy.subject | L5: | | M5: =IF(LEN(TRIM(Q5))>0,Q5,R5) -> PatientModule | N5: | | Q5: =IF(LEN(A5)>0,_xlfn.IFNA(_xlfn.XLOOKUP(A5,KOS!U:U,KOS!N:N),""),"") -> PatientModule | R5: =IF(LEN(A5)>0,_xlfn.IFNA(_xlfn.XLOOKUP(A5,'KOS SR'!X:X,'KOS SR'!N:N),""),"")
A6: EHDSImagingStudy4 | B6: EHDSImagingStudy | C6: header.identifier | D6: 1..* | E6: Identifier | F6: =SUBSTITUTE(E6," http://www.xt-ehr.eu/fhir/models/StructureDefinition/", "" ) -> Identifier | H6: | | I6: =B6&IF(LEN(TRIM(C6))>0,"-","")&C6 -> EHDSImagingStudy- header.identifier | J6: | | K6: =IF(LEN(A6)>0,_xlfn.IFNA(_xlfn.XLOOKUP(A6,FHIR!M:M,FHIR!E:E),""),"") -> ImagingStudy.identifier[studyInstanceUid] | L6: | | M6: =IF(LEN(TRIM(Q6))>0,Q6,R6) -> General Study-StudyInstanceUID | N6: | | Q6: =IF(LEN(A6)>0,_xlfn.IFNA(_xlfn.XLOOKUP(A6,KOS!U:U,KOS!N:N),""),"") -> General Study-StudyInstanceUID | R6: =IF(LEN(A6)>0,_xlfn.IFNA(_xlfn.XLOOKUP(A6,'KOS SR'!X:X,'KOS SR'!N:N),""),"") -> SR-TID1600:EV (ddd011, DCM, “Study Instance UID”)
A7: EHDSImagingStudy5 | B7: EHDSImagingStudy | C7: header.author[x] | D7: 1..* | E7: http://www.xt-ehr.eu/fhir/models/StructureDefinition/EHDSHealthProfessional | F7: =SUBSTITUTE(E7," http://www.xt-ehr.eu/fhir/models/StructureDefinition/", "" ) -> EHDSHealthProfessional | H7: | | I7: =B7&IF(LEN(TRIM(C7))>0,"-","")&C7 -> EHDSImagingStudy- header.author[x] | J7: | | K7: =IF(LEN(A7)>0,_xlfn.IFNA(_xlfn.XLOOKUP(A7,FHIR!M:M,FHIR!E:E),""),"") | L7: | | M7: =IF(LEN(TRIM(Q7))>0,Q7,R7) | N7: | | Q7: =IF(LEN(A7)>0,_xlfn.IFNA(_xlfn.XLOOKUP(A7,KOS!U:U,KOS!N:N),""),"") | R7: =IF(LEN(A7)>0,_xlfn.IFNA(_xlfn.XLOOKUP(A7,'KOS SR'!X:X,'KOS SR'!N:N),""),"")
A8: EHDSImagingStudy6 | B8: EHDSImagingStudy | C8: header.author[EHDSOrganization] | D8: 1..* | E8: http://www.xt-ehr.eu/fhir/models/StructureDefinition/EHDSOrganisation | F8: =SUBSTITUTE(E8," http://www.xt-ehr.eu/fhir/models/StructureDefinition/", "" ) -> EHDSOrganisation | H8: | | I8: =B8&IF(LEN(TRIM(C8))>0,"-","")&C8 -> EHDSImagingStudy- header.author[EHDSOrganization] | J8: | | K8: =IF(LEN(A8)>0,_xlfn.IFNA(_xlfn.XLOOKUP(A8,FHIR!M:M,FHIR!E:E),""),"") -> MhDDocumentReference.author[organization] | L8: | | M8: =IF(LEN(TRIM(Q8))>0,Q8,R8) -> General Equipment-Institution Name | N8: | | Q8: =IF(LEN(A8)>0,_xlfn.IFNA(_xlfn.XLOOKUP(A8,KOS!U:U,KOS!N:N),""),"") -> General Equipment-Institution Name | R8: =IF(LEN(A8)>0,_xlfn.IFNA(_xlfn.XLOOKUP(A8,'KOS SR'!X:X,'KOS SR'!N:N),""),"")
A9: EHDSImagingStudy7 | B9: EHDSImagingStudy | C9: header.author[EHDSDevice] | D9: 1..* | E9: http://www.xt-ehr.eu/fhir/models/StructureDefinition/EHDSDevice | F9: =SUBSTITUTE(E9," http://www.xt-ehr.eu/fhir/models/StructureDefinition/", "" ) -> EHDSDevice | H9: | | I9: =B9&IF(LEN(TRIM(C9))>0,"-","")&C9 -> EHDSImagingStudy- header.author[EHDSDevice] | J9: | | K9: =IF(LEN(A9)>0,_xlfn.IFNA(_xlfn.XLOOKUP(A9,FHIR!M:M,FHIR!E:E),""),"") -> MhDDocumentReference.author[madoDevice] | L9: | | M9: =IF(LEN(TRIM(Q9))>0,Q9,R9) -> General Equipment-Manufacturer | N9: | | Q9: =IF(LEN(A9)>0,_xlfn.IFNA(_xlfn.XLOOKUP(A9,KOS!U:U,KOS!N:N),""),"") -> General Equipment-Manufacturer | R9: =IF(LEN(A9)>0,_xlfn.IFNA(_xlfn.XLOOKUP(A9,'KOS SR'!X:X,'KOS SR'!N:N),""),"")
A10: EHDSImagingStudy8 | B10: EHDSImagingStudy | C10: header.date | D10: 1..1 | E10: dateTime | F10: =SUBSTITUTE(E10," http://www.xt-ehr.eu/fhir/models/StructureDefinition/", "" ) -> dateTime | H10: | | I10: =B10&IF(LEN(TRIM(C10))>0,"-","")&C10 -> EHDSImagingStudy- header.date | J10: | | K10: =IF(LEN(A10)>0,_xlfn.IFNA(_xlfn.XLOOKUP(A10,FHIR!M:M,FHIR!E:E),""),"") | L10: | | M10: =IF(LEN(TRIM(Q10))>0,Q10,R10) -> Key Object Document-Content Date | N10: | | Q10: =IF(LEN(A10)>0,_xlfn.IFNA(_xlfn.XLOOKUP(A10,KOS!U:U,KOS!N:N),""),"") -> Key Object Document-Content Date | R10: =IF(LEN(A10)>0,_xlfn.IFNA(_xlfn.XLOOKUP(A10,'KOS SR'!X:X,'KOS SR'!N:N),""),"")
A11: EHDSImagingStudy9 | B11: EHDSImagingStudy | C11: header.status | D11: 1..1 | E11: CodeableConcept | F11: =SUBSTITUTE(E11," http://www.xt-ehr.eu/fhir/models/StructureDefinition/", "" ) -> CodeableConcept | H11: | | I11: =B11&IF(LEN(TRIM(C11))>0,"-","")&C11 -> EHDSImagingStudy- header.status | J11: | | K11: =IF(LEN(A11)>0,_xlfn.IFNA(_xlfn.XLOOKUP(A11,FHIR!M:M,FHIR!E:E),""),"") -> ImagingStudy.status | L11: | | M11: =IF(LEN(TRIM(Q11))>0,Q11,R11) | N11: | | Q11: =IF(LEN(A11)>0,_xlfn.IFNA(_xlfn.XLOOKUP(A11,KOS!U:U,KOS!N:N),""),"") | R11: =IF(LEN(A11)>0,_xlfn.IFNA(_xlfn.XLOOKUP(A11,'KOS SR'!X:X,'KOS SR'!N:N),""),"")
A12: EHDSImagingStudy10 | B12: EHDSImagingStudy | C12: header.language | D12: 0..1 | E12: CodeableConcept | F12: =SUBSTITUTE(E12," http://www.xt-ehr.eu/fhir/models/StructureDefinition/", "" ) -> CodeableConcept | H12: | | I12: =B12&IF(LEN(TRIM(C12))>0,"-","")&C12 -> EHDSImagingStudy- header.language | J12: | | K12: =IF(LEN(A12)>0,_xlfn.IFNA(_xlfn.XLOOKUP(A12,FHIR!M:M,FHIR!E:E),""),"") -> ImagingStudy.language | L12: | | M12: =IF(LEN(TRIM(Q12))>0,Q12,R12) | N12: | | Q12: =IF(LEN(A12)>0,_xlfn.IFNA(_xlfn.XLOOKUP(A12,KOS!U:U,KOS!N:N),""),"") | R12: =IF(LEN(A12)>0,_xlfn.IFNA(_xlfn.XLOOKUP(A12,'KOS SR'!X:X,'KOS SR'!N:N),""),"")
A13: EHDSImagingStudy11 | B13: EHDSImagingStudy | C13: modality | D13: 0..* | E13: CodeableConcept | F13: =SUBSTITUTE(E13," http://www.xt-ehr.eu/fhir/models/StructureDefinition/", "" ) -> CodeableConcept | H13: | | I13: =B13&IF(LEN(TRIM(C13))>0,"-","")&C13 -> EHDSImagingStudy- modality | J13: | | K13: =IF(LEN(A13)>0,_xlfn.IFNA(_xlfn.XLOOKUP(A13,FHIR!M:M,FHIR!E:E),""),"") -> ImagingStudy.modality | L13: | | M13: =IF(LEN(TRIM(Q13))>0,Q13,R13) -> General Study-Modality | N13: | | Q13: =IF(LEN(A13)>0,_xlfn.IFNA(_xlfn.XLOOKUP(A13,KOS!U:U,KOS!N:N),""),"") -> General Study-Modality | R13: =IF(LEN(A13)>0,_xlfn.IFNA(_xlfn.XLOOKUP(A13,'KOS SR'!X:X,'KOS SR'!N:N),""),"") -> SR-TID1600:EV (121139, DCM, "Modality")
A14: EHDSImagingStudy12 | B14: EHDSImagingStudy | C14: bodySite | D14: 0..* | E14: http://www.xt-ehr.eu/fhir/models/StructureDefinition/EHDSBodyStructure | F14: =SUBSTITUTE(E14," http://www.xt-ehr.eu/fhir/models/StructureDefinition/", "" ) -> EHDSBodyStructure | H14: | | I14: =B14&IF(LEN(TRIM(C14))>0,"-","")&C14 -> EHDSImagingStudy- bodySite | J14: | | K14: =IF(LEN(A14)>0,_xlfn.IFNA(_xlfn.XLOOKUP(A14,FHIR!M:M,FHIR!E:E),""),"") -> ImagingStudy.extension[anatomical] | L14: | | M14: =IF(LEN(TRIM(Q14))>0,Q14,R14) -> SR-TID1600:EV (123014, DCM, "Target Region") | N14: | | Q14: =IF(LEN(A14)>0,_xlfn.IFNA(_xlfn.XLOOKUP(A14,KOS!U:U,KOS!N:N),""),"") | R14: =IF(LEN(A14)>0,_xlfn.IFNA(_xlfn.XLOOKUP(A14,'KOS SR'!X:X,'KOS SR'!N:N),""),"") -> SR-TID1600:EV (123014, DCM, "Target Region")
A15: EHDSImagingStudy13 | B15: EHDSImagingStudy | C15: encounter | D15: 0..1 | E15: http://www.xt-ehr.eu/fhir/models/StructureDefinition/EHDSEncounter | F15: =SUBSTITUTE(E15," http://www.xt-ehr.eu/fhir/models/StructureDefinition/", "" ) -> EHDSEncounter | H15: | | I15: =B15&IF(LEN(TRIM(C15))>0,"-","")&C15 -> EHDSImagingStudy- encounter | J15: | | K15: =IF(LEN(A15)>0,_xlfn.IFNA(_xlfn.XLOOKUP(A15,FHIR!M:M,FHIR!E:E),""),"") -> ImagingStudy.encounter | L15: | | M15: =IF(LEN(TRIM(Q15))>0,Q15,R15) | N15: | | Q15: =IF(LEN(A15)>0,_xlfn.IFNA(_xlfn.XLOOKUP(A15,KOS!U:U,KOS!N:N),""),"") | R15: =IF(LEN(A15)>0,_xlfn.IFNA(_xlfn.XLOOKUP(A15,'KOS SR'!X:X,'KOS SR'!N:N),""),"")
A16: EHDSImagingStudy14 | B16: EHDSImagingStudy | C16: started | D16: 0..1 | E16: dateTime | F16: =SUBSTITUTE(E16," http://www.xt-ehr.eu/fhir/models/StructureDefinition/", "" ) -> dateTime | H16: | | I16: =B16&IF(LEN(TRIM(C16))>0,"-","")&C16 -> EHDSImagingStudy- started | J16: | | K16: =IF(LEN(A16)>0,_xlfn.IFNA(_xlfn.XLOOKUP(A16,FHIR!M:M,FHIR!E:E),""),"") -> ImagingStudy.started | L16: | | M16: =IF(LEN(TRIM(Q16))>0,Q16,R16) -> General Study-StudyDate | N16: | | Q16: =IF(LEN(A16)>0,_xlfn.IFNA(_xlfn.XLOOKUP(A16,KOS!U:U,KOS!N:N),""),"") -> General Study-StudyDate | R16: =IF(LEN(A16)>0,_xlfn.IFNA(_xlfn.XLOOKUP(A16,'KOS SR'!X:X,'KOS SR'!N:N),""),"")
... A38: EHDSImagingStudy36 | B38: EHDSImagingStudy | C38: series.instancesInTheSeries.numberOfFrames | D38: 0..1 | E38: integer | F38: =SUBSTITUTE(E38," http://www.xt-ehr.eu/fhir/models/StructureDefinition/", "" ) -> integer | H38: | | I38: =B38&IF(LEN(TRIM(C38))>0,"-","")&C38 -> EHDSImagingStudy- series.instancesInTheSeries.numberOfFrames | J38: | | K38: =IF(LEN(A38)>0,_xlfn.IFNA(_xlfn.XLOOKUP(A38,FHIR!M:M,FHIR!E:E),""),"") -> ImagingStudy.series.instance.extension[numberOfFrames] | L38: | | M38: =IF(LEN(TRIM(Q38))>0,Q38,R38) -> SR-TID1601:EV (121140, DCM, “Number of Frames”) | N38: | | Q38: =IF(LEN(A38)>0,_xlfn.IFNA(_xlfn.XLOOKUP(A38,KOS!U:U,KOS!N:N),""),"") | R38: =IF(LEN(A38)>0,_xlfn.IFNA(_xlfn.XLOOKUP(A38,'KOS SR'!X:X,'KOS SR'!N:N),""),"") -> SR-TID1601:EV (121140, DCM, “Number of Frames”)
A39: EHDSImagingStudy37 | B39: EHDSImagingStudy | C39: series.instancesInTheSeries.keyImage | D39: 0..* | E39: Base | F39: =SUBSTITUTE(E39," http://www.xt-ehr.eu/fhir/models/StructureDefinition/", "" ) -> Base | G39: Remove? | H39: | | I39: =B39&IF(LEN(TRIM(C39))>0,"-","")&C39 -> EHDSImagingStudy- series.instancesInTheSeries.keyImage | J39: | | K39: =IF(LEN(A39)>0,_xlfn.IFNA(_xlfn.XLOOKUP(A39,FHIR!M:M,FHIR!E:E),""),"") | L39: | | M39: =IF(LEN(TRIM(Q39))>0,Q39,R39) | N39: | | Q39: =IF(LEN(A39)>0,_xlfn.IFNA(_xlfn.XLOOKUP(A39,KOS!U:U,KOS!N:N),""),"") | R39: =IF(LEN(A39)>0,_xlfn.IFNA(_xlfn.XLOOKUP(A39,'KOS SR'!X:X,'KOS SR'!N:N),""),"")
A40: EHDSImagingStudy38 | B40: EHDSImagingStudy | C40: series.instancesInTheSeries.keyImage.flag | D40: 1..1 | E40: CodeableConcept | F40: =SUBSTITUTE(E40," http://www.xt-ehr.eu/fhir/models/StructureDefinition/", "" ) -> CodeableConcept | G40: Remove? | H40: | | I40: =B40&IF(LEN(TRIM(C40))>0,"-","")&C40 -> EHDSImagingStudy- series.instancesInTheSeries.keyImage.flag | J40: | | K40: =IF(LEN(A40)>0,_xlfn.IFNA(_xlfn.XLOOKUP(A40,FHIR!M:M,FHIR!E:E),""),"") -> Basic-KeyObj.extension[code].coding | L40: | | M40: =IF(LEN(TRIM(Q40))>0,Q40,R40) | N40: | | Q40: =IF(LEN(A40)>0,_xlfn.IFNA(_xlfn.XLOOKUP(A40,KOS!U:U,KOS!N:N),""),"") | R40: =IF(LEN(A40)>0,_xlfn.IFNA(_xlfn.XLOOKUP(A40,'KOS SR'!X:X,'KOS SR'!N:N),""),"")
A41: EHDSImagingStudy39 | B41: EHDSImagingStudy | C41: series.instancesInTheSeries.keyImage.reason | D41: 0..1 | E41: string | F41: =SUBSTITUTE(E41," http://www.xt-ehr.eu/fhir/models/StructureDefinition/", "" ) -> string | G41: Remove? | H41: | | I41: =B41&IF(LEN(TRIM(C41))>0,"-","")&C41 -> EHDSImagingStudy- series.instancesInTheSeries.keyImage.reason | J41: | | K41: =IF(LEN(A41)>0,_xlfn.IFNA(_xlfn.XLOOKUP(A41,FHIR!M:M,FHIR!E:E),""),"") -> Basic-KeyObj.extension[code].text | L41: | | M41: =IF(LEN(TRIM(Q41))>0,Q41,R41) | N41: | | Q41: =IF(LEN(A41)>0,_xlfn.IFNA(_xlfn.XLOOKUP(A41,KOS!U:U,KOS!N:N),""),"") | R41: =IF(LEN(A41)>0,_xlfn.IFNA(_xlfn.XLOOKUP(A41,'KOS SR'!X:X,'KOS SR'!N:N),""),"")
A42: EHDSImagingStudy40 | B42: EHDSImagingStudy | C42: series.instancesInTheSeries.keyImage.seriesUID | D42: 1..* | E42: Identifier | F42: =SUBSTITUTE(E42," http://www.xt-ehr.eu/fhir/models/StructureDefinition/", "" ) -> Identifier | G42: Remove? | H42: | | I42: =B42&IF(LEN(TRIM(C42))>0,"-","")&C42 -> EHDSImagingStudy- series.instancesInTheSeries.keyImage.seriesUID | J42: | | K42: =IF(LEN(A42)>0,_xlfn.IFNA(_xlfn.XLOOKUP(A42,FHIR!M:M,FHIR!E:E),""),"") -> Basic-KeyObj.extension[seriesUid] | L42: | | M42: =IF(LEN(TRIM(Q42))>0,Q42,R42) | N42: | | Q42: =IF(LEN(A42)>0,_xlfn.IFNA(_xlfn.XLOOKUP(A42,KOS!U:U,KOS!N:N),""),"") | R42: =IF(LEN(A42)>0,_xlfn.IFNA(_xlfn.XLOOKUP(A42,'KOS SR'!X:X,'KOS SR'!N:N),""),"")
A43: EHDSImagingStudy41 | B43: EHDSImagingStudy | C43: series.instancesInTheSeries.keyImage.instanceUID | D43: 1..* | E43: Identifier | F43: =SUBSTITUTE(E43," http://www.xt-ehr.eu/fhir/models/StructureDefinition/", "" ) -> Identifier | G43: Remove? | H43: | | I43: =B43&IF(LEN(TRIM(C43))>0,"-","")&C43 -> EHDSImagingStudy- series.instancesInTheSeries.keyImage.instanceUID | J43: | | K43: =IF(LEN(A43)>0,_xlfn.IFNA(_xlfn.XLOOKUP(A43,FHIR!M:M,FHIR!E:E),""),"") -> Basic-KeyObj.extension[studyUid] | L43: | | M43: =IF(LEN(TRIM(Q43))>0,Q43,R43) | N43: | | Q43: =IF(LEN(A43)>0,_xlfn.IFNA(_xlfn.XLOOKUP(A43,KOS!U:U,KOS!N:N),""),"") | R43: =IF(LEN(A43)>0,_xlfn.IFNA(_xlfn.XLOOKUP(A43,'KOS SR'!X:X,'KOS SR'!N:N),""),"")
H45: | | I45: XtEHR | J45: | | K45: FHIR R4 | L45: | | M45: KOS | N45: |
H46: | | I46: ----------- | J46: | | K46: ----------- | L46: | | M46: ----------- | N46: |
A47: EHDSPatient1 | B47: EHDSPatient | D47: 0..* | E47: Model for information about a patient (subject of care). | H47: | | I47: =B47&IF(LEN(TRIM(C47))>0,"-","")&C47 -> EHDSPatient | J47: | | K47: =IF(LEN(A47)>0,_xlfn.IFNA(_xlfn.XLOOKUP(A47,FHIR!M:M,FHIR!E:E),""),"") | L47: | | M47: =IF(LEN(TRIM(Q47))>0,Q47,R47) | N47: | | Q47: =IF(LEN(A47)>0,_xlfn.IFNA(_xlfn.XLOOKUP(A47,KOS!U:U,KOS!N:N),""),"") | R47: =IF(LEN(A47)>0,_xlfn.IFNA(_xlfn.XLOOKUP(A47,'KOS SR'!X:X,'KOS SR'!N:N),""),"")
A48: EHDSPatient2 | B48: EHDSPatient | C48: identifier | D48: 1..* | E48: An identifier of the patient that is unique within a defined scope (typically a national patient identifier, but it can also be a temporary identifier issued by the EHR). | F48: Identifier | H48: | | I48: =B48&IF(LEN(TRIM(C48))>0,"-","")&C48 -> EHDSPatient- identifier | J48: | | K48: =IF(LEN(A48)>0,_xlfn.IFNA(_xlfn.XLOOKUP(A48,FHIR!M:M,FHIR!E:E),""),"") -> Patient.identifier | L48: | | M48: =IF(LEN(TRIM(Q48))>0,Q48,R48) -> PatientModule-Patient ID​ | N48: | | Q48: =IF(LEN(A48)>0,_xlfn.IFNA(_xlfn.XLOOKUP(A48,KOS!U:U,KOS!N:N),""),"") -> PatientModule-Patient ID​ | R48: =IF(LEN(A48)>0,_xlfn.IFNA(_xlfn.XLOOKUP(A48,'KOS SR'!X:X,'KOS SR'!N:N),""),"") | X48: PatientID | Y48: IssuerOfPatientID | Z48: IssuerOfPatientIdSequence | AA48: OtherPatientIDsSequence
A49: EHDSPatient3 | B49: EHDSPatient | C49: name | D49: 0..* | E49: Name might consist of name parts, e.g. Given name or names, family name/surname, name prefix etc. | F49: http://www.xt-ehr.eu/fhir/models/StructureDefinition/EHDSHumanName | H49: | | I49: =B49&IF(LEN(TRIM(C49))>0,"-","")&C49 -> EHDSPatient- name | J49: | | K49: =IF(LEN(A49)>0,_xlfn.IFNA(_xlfn.XLOOKUP(A49,FHIR!M:M,FHIR!E:E),""),"") -> Patient.name | L49: | | M49: =IF(LEN(TRIM(Q49))>0,Q49,R49) -> PatientModule-PatientName | N49: | | Q49: =IF(LEN(A49)>0,_xlfn.IFNA(_xlfn.XLOOKUP(A49,KOS!U:U,KOS!N:N),""),"") -> PatientModule-PatientName | R49: =IF(LEN(A49)>0,_xlfn.IFNA(_xlfn.XLOOKUP(A49,'KOS SR'!X:X,'KOS SR'!N:N),""),"")
A50: EHDSPatient4 | B50: EHDSPatient | C50: dateOfBirth | D50: 0..1 | E50: Date of birth | F50: dateTime | H50: | | I50: =B50&IF(LEN(TRIM(C50))>0,"-","")&C50 -> EHDSPatient- dateOfBirth | J50: | | K50: =IF(LEN(A50)>0,_xlfn.IFNA(_xlfn.XLOOKUP(A50,FHIR!M:M,FHIR!E:E),""),"") -> Patient.birthDate | L50: | | M50: =IF(LEN(TRIM(Q50))>0,Q50,R50) -> PatientModule-Patient's Birth Date​ | N50: | | Q50: =IF(LEN(A50)>0,_xlfn.IFNA(_xlfn.XLOOKUP(A50,KOS!U:U,KOS!N:N),""),"") -> PatientModule-Patient's Birth Date​ | R50: =IF(LEN(A50)>0,_xlfn.IFNA(_xlfn.XLOOKUP(A50,'KOS SR'!X:X,'KOS SR'!N:N),""),"")
A51: EHDSPatient5 | B51: EHDSPatient | C51: deceased[boolean] | D51: 0..1 | E51: Whether the patient is deceased or date of death. | F51: boolean | H51: | | I51: =B51&IF(LEN(TRIM(C51))>0,"-","")&C51 -> EHDSPatient- deceased[boolean] | J51: | | K51: =IF(LEN(A51)>0,_xlfn.IFNA(_xlfn.XLOOKUP(A51,FHIR!M:M,FHIR!E:E),""),"") -> Patient.deceased[boolean] | L51: | | M51: =IF(LEN(TRIM(Q51))>0,Q51,R51) | N51: | | Q51: =IF(LEN(A51)>0,_xlfn.IFNA(_xlfn.XLOOKUP(A51,KOS!U:U,KOS!N:N),""),"") | R51: =IF(LEN(A51)>0,_xlfn.IFNA(_xlfn.XLOOKUP(A51,'KOS SR'!X:X,'KOS SR'!N:N),""),"")
A52: EHDSPatient6 | B52: EHDSPatient | C52: deceased[DateTime] | D52: 0..1 | E52: Whether the patient is deceased or date of death. | F52: dateTime | H52: | | I52: =B52&IF(LEN(TRIM(C52))>0,"-","")&C52 -> EHDSPatient- deceased[DateTime] | J52: | | K52: =IF(LEN(A52)>0,_xlfn.IFNA(_xlfn.XLOOKUP(A52,FHIR!M:M,FHIR!E:E),""),"") -> Patient.deceased[DateTime] | L52: | | M52: =IF(LEN(TRIM(Q52))>0,Q52,R52) | N52: | | Q52: =IF(LEN(A52)>0,_xlfn.IFNA(_xlfn.XLOOKUP(A52,KOS!U:U,KOS!N:N),""),"") | R52: =IF(LEN(A52)>0,_xlfn.IFNA(_xlfn.XLOOKUP(A52,'KOS SR'!X:X,'KOS SR'!N:N),""),"")
A53: EHDSPatient7 | B53: EHDSPatient | C53: administrativeGender | D53: 0..1 | E53: This field must contain a recognised valid value for "administrative gender". If different, "physiological gender" should be communicated elsewhere. | F53: CodeableConcept | G53: HL7 Administrative Gender (preferred) | H53: | | I53: =B53&IF(LEN(TRIM(C53))>0,"-","")&C53 -> EHDSPatient- administrativeGender | J53: | | K53: =IF(LEN(A53)>0,_xlfn.IFNA(_xlfn.XLOOKUP(A53,FHIR!M:M,FHIR!E:E),""),"") -> Patient.gender | L53: | | M53: =IF(LEN(TRIM(Q53))>0,Q53,R53) -> PatientModule-Patient's Sex​ | N53: | | Q53: =IF(LEN(A53)>0,_xlfn.IFNA(_xlfn.XLOOKUP(A53,KOS!U:U,KOS!N:N),""),"") -> PatientModule-Patient's Sex​ | R53: =IF(LEN(A53)>0,_xlfn.IFNA(_xlfn.XLOOKUP(A53,'KOS SR'!X:X,'KOS SR'!N:N),""),"")
A54: EHDSPatient8 | B54: EHDSPatient | C54: address | D54: 0..* | E54: The addresses are always sequences of address parts (e.g. street address line, country, postal code, city) even if postal address formats may vary depending on the country. An address may or may not include a specific use code, if this attribute is not present it is assumed to be the default address useful for any purpose. | F54: http://www.xt-ehr.eu/fhir/models/StructureDefinition/EHDSAddress | H54: | | I54: =B54&IF(LEN(TRIM(C54))>0,"-","")&C54 -> EHDSPatient- address | J54: | | K54: =IF(LEN(A54)>0,_xlfn.IFNA(_xlfn.XLOOKUP(A54,FHIR!M:M,FHIR!E:E),""),"") -> Patient.address | L54: | | M54: =IF(LEN(TRIM(Q54))>0,Q54,R54) | N54: | | Q54: =IF(LEN(A54)>0,_xlfn.IFNA(_xlfn.XLOOKUP(A54,KOS!U:U,KOS!N:N),""),"") | R54: =IF(LEN(A54)>0,_xlfn.IFNA(_xlfn.XLOOKUP(A54,'KOS SR'!X:X,'KOS SR'!N:N),""),"")
A55: EHDSPatient9 | B55: EHDSPatient | C55: telecom | D55: 0..* | E55: Contact information. | F55: http://www.xt-ehr.eu/fhir/models/StructureDefinition/EHDSTelecom | H55: | | I55: =B55&IF(LEN(TRIM(C55))>0,"-","")&C55 -> EHDSPatient- telecom | J55: | | K55: =IF(LEN(A55)>0,_xlfn.IFNA(_xlfn.XLOOKUP(A55,FHIR!M:M,FHIR!E:E),""),"") -> Patient.telecom | L55: | | M55: =IF(LEN(TRIM(Q55))>0,Q55,R55) | N55: | | Q55: =IF(LEN(A55)>0,_xlfn.IFNA(_xlfn.XLOOKUP(A55,KOS!U:U,KOS!N:N),""),"") | R55: =IF(LEN(A55)>0,_xlfn.IFNA(_xlfn.XLOOKUP(A55,'KOS SR'!X:X,'KOS SR'!N:N),""),"")
H57: | | I57: XtEHR | J57: | | K57: FHIR R4 | L57: | | M57: KOS | N57: |
H58: | | I58: ----------- | J58: | | K58: ----------- | L58: | | M58: ----------- | N58: |
A59: EHDSEndpoint1 | B59: EHDSEndpoint | D59: 0..* | E59: Model covers technical details of an endpoint that can be used for electronic services | H59: | | I59: =B59&IF(LEN(TRIM(C59))>0,"-","")&C59 -> EHDSEndpoint | J59: | | K59: =IF(LEN(A59)>0,_xlfn.IFNA(_xlfn.XLOOKUP(A59,FHIR!M:M,FHIR!E:E),""),"") | L59: | | M59: =IF(LEN(TRIM(Q59))>0,Q59,R59) | N59: | | Q59: =IF(LEN(A59)>0,_xlfn.IFNA(_xlfn.XLOOKUP(A59,KOS!U:U,KOS!N:N),""),"") | R59: =IF(LEN(A59)>0,_xlfn.IFNA(_xlfn.XLOOKUP(A59,'KOS SR'!X:X,'KOS SR'!N:N),""),"")
A60: EHDSEndpoint2 | B60: EHDSEndpoint | C60: identifier | D60: 1..* | E60: Identifier for the endpoint | F60: Identifier | H60: | | I60: =B60&IF(LEN(TRIM(C60))>0,"-","")&C60 -> EHDSEndpoint- identifier | J60: | | K60: =IF(LEN(A60)>0,_xlfn.IFNA(_xlfn.XLOOKUP(A60,FHIR!M:M,FHIR!E:E),""),"") -> Endpoint-XcWADO.identifier | L60: | | M60: =IF(LEN(TRIM(Q60))>0,Q60,R60) | N60: | | Q60: =IF(LEN(A60)>0,_xlfn.IFNA(_xlfn.XLOOKUP(A60,KOS!U:U,KOS!N:N),""),"") | R60: =IF(LEN(A60)>0,_xlfn.IFNA(_xlfn.XLOOKUP(A60,'KOS SR'!X:X,'KOS SR'!N:N),""),"")
A61: EHDSEndpoint3 | B61: EHDSEndpoint | C61: status | D61: 1..1 | E61: Status of the endpoint (e.g. active, limited). | F61: CodeableConcept | G61: HL7 Endpoint Status (preferred) | H61: | | I61: =B61&IF(LEN(TRIM(C61))>0,"-","")&C61 -> EHDSEndpoint- status | J61: | | K61: =IF(LEN(A61)>0,_xlfn.IFNA(_xlfn.XLOOKUP(A61,FHIR!M:M,FHIR!E:E),""),"") -> Endpoint-XcWADO.status | L61: | | M61: =IF(LEN(TRIM(Q61))>0,Q61,R61) | N61: | | Q61: =IF(LEN(A61)>0,_xlfn.IFNA(_xlfn.XLOOKUP(A61,KOS!U:U,KOS!N:N),""),"") | R61: =IF(LEN(A61)>0,_xlfn.IFNA(_xlfn.XLOOKUP(A61,'KOS SR'!X:X,'KOS SR'!N:N),""),"")
A62: EHDSEndpoint4 | B62: EHDSEndpoint | C62: connectionType | D62: 1..* | E62: A coded value that represents the technical details of the usage of this endpoint, such as what WSDLs should be used in what way. | F62: CodeableConcept | H62: | | I62: =B62&IF(LEN(TRIM(C62))>0,"-","")&C62 -> EHDSEndpoint- connectionType | J62: | | K62: =IF(LEN(A62)>0,_xlfn.IFNA(_xlfn.XLOOKUP(A62,FHIR!M:M,FHIR!E:E),""),"") -> Endpoint-XcWADO.connectionType | L62: | | M62: =IF(LEN(TRIM(Q62))>0,Q62,R62) | N62: | | Q62: =IF(LEN(A62)>0,_xlfn.IFNA(_xlfn.XLOOKUP(A62,KOS!U:U,KOS!N:N),""),"") | R62: =IF(LEN(A62)>0,_xlfn.IFNA(_xlfn.XLOOKUP(A62,'KOS SR'!X:X,'KOS SR'!N:N),""),"")
A63: EHDSEndpoint5 | B63: EHDSEndpoint | C63: name | D63: 0..1 | E63: A friendly name that this endpoint can be referred to with. | F63: string | H63: | | I63: =B63&IF(LEN(TRIM(C63))>0,"-","")&C63 -> EHDSEndpoint- name | J63: | | K63: =IF(LEN(A63)>0,_xlfn.IFNA(_xlfn.XLOOKUP(A63,FHIR!M:M,FHIR!E:E),""),"") -> Endpoint-XcWADO.name | L63: | | M63: =IF(LEN(TRIM(Q63))>0,Q63,R63) | N63: | | Q63: =IF(LEN(A63)>0,_xlfn.IFNA(_xlfn.XLOOKUP(A63,KOS!U:U,KOS!N:N),""),"") | R63: =IF(LEN(A63)>0,_xlfn.IFNA(_xlfn.XLOOKUP(A63,'KOS SR'!X:X,'KOS SR'!N:N),""),"")
...

Sheet KOS
A1: IE | B1: Module | C1: Reference | I1: value | J1: DICOM | K1: MADO | M1: | | N1: KOS path | O1: | | P1: FHIR | Q1: | | R1: XtEHR | S1: | | U1: XtEHR | Z1: FHIR
M2: | | N2: -------- | O2: | | P2: -------- | Q2: | | R2: -------- | S2: |
A3: Patient | B3: PatientModule | C3: C.7.1.1 | D3: PatientModule | J3: 2 | K3: R+ | M3: | | N3: =D3&IF(LEN(E3)>0,"-","")&E3&IF(LEN(F3)>0,"-","")&F3&IF(LEN(G3)>0,"-","")&G3&IF(LEN(H3)>0,"-","")&H3 -> PatientModule | O3: | | Q3: | | R3: =+V3 -> EHDSImagingStudy.header.subject | S3: | | U3: EHDSImagingStudy3 | V3: =_xlfn.IFNA(VLOOKUP($U3, XtEHR!A:F,2,FALSE)&"."&TRIM(VLOOKUP($U3, XtEHR!A:F,3,FALSE)),"-") -> EHDSImagingStudy.header.subject | AA3: =IF(LEN(Z3)>0,_xlfn.XLOOKUP(Z3,FHIR!A:A,FHIR!E:E),"")
B4: PatientModule | C4: C.7.1.1 | D4: PatientModule | E4: PatientName | J4: 2 | K4: R+ | M4: | | N4: =D4&IF(LEN(E4)>0,"-","")&E4&IF(LEN(F4)>0,"-","")&F4&IF(LEN(G4)>0,"-","")&G4&IF(LEN(H4)>0,"-","")&H4 -> PatientModule-PatientName | O4: | | P4: =+AA4 -> Patient.name | Q4: | | R4: =+V4 -> EHDSPatient.name | S4: | | U4: EHDSPatient3 | V4: =_xlfn.IFNA(VLOOKUP($U4, XtEHR!A:F,2,FALSE)&"."&TRIM(VLOOKUP($U4, XtEHR!A:F,3,FALSE)),"-") -> EHDSPatient.name | Z4: Patient2 | AA4: =IF(LEN(Z4)>0,_xlfn.XLOOKUP(Z4,FHIR!A:A,FHIR!E:E),"") -> Patient.name
B5: PatientModule | D5: PatientModule | E5: Patient ID​ | J5: 2 | K5: R+ | M5: | | N5: =D5&IF(LEN(E5)>0,"-","")&E5&IF(LEN(F5)>0,"-","")&F5&IF(LEN(G5)>0,"-","")&G5&IF(LEN(H5)>0,"-","")&H5 -> PatientModule-Patient ID​ | O5: | | P5: =+AA5 -> Patient.identifier | Q5: | | R5: =+V5 -> EHDSPatient.identifier | S5: | | U5: EHDSPatient2 | V5: =_xlfn.IFNA(VLOOKUP($U5, XtEHR!A:F,2,FALSE)&"."&TRIM(VLOOKUP($U5, XtEHR!A:F,3,FALSE)),"-") -> EHDSPatient.identifier | Z5: Patient1 | AA5: =IF(LEN(Z5)>0,_xlfn.XLOOKUP(Z5,FHIR!A:A,FHIR!E:E),"") -> Patient.identifier | AD5: value
B6: PatientModule | D6: PatientModule | E6: Issuer of Patient ID | J6: 2 | K6: R+ | M6: | | N6: =D6&IF(LEN(E6)>0,"-","")&E6&IF(LEN(F6)>0,"-","")&F6&IF(LEN(G6)>0,"-","")&G6&IF(LEN(H6)>0,"-","")&H6 -> PatientModule-Issuer of Patient ID | O6: | | P6: =+AA6 -> Patient.identifier | Q6: | | R6: =+V6 -> EHDSPatient.identifier | S6: | | U6: EHDSPatient2 | V6: =_xlfn.IFNA(VLOOKUP($U6, XtEHR!A:F,2,FALSE)&"."&TRIM(VLOOKUP($U6, XtEHR!A:F,3,FALSE)),"-") -> EHDSPatient.identifier | Z6: Patient1 | AA6: =IF(LEN(Z6)>0,_xlfn.XLOOKUP(Z6,FHIR!A:A,FHIR!E:E),"") -> Patient.identifier | AD6: system
B7: PatientModule | D7: PatientModule | E7: Issuer of Patient ID Qualifiers Sequence | M7: | | N7: =D7&IF(LEN(E7)>0,"-","")&E7&IF(LEN(F7)>0,"-","")&F7&IF(LEN(G7)>0,"-","")&G7&IF(LEN(H7)>0,"-","")&H7 -> PatientModule-Issuer of Patient ID Qualifiers Sequence | O7: | | P7: =+AA7 -> Patient.identifier | Q7: | | R7: =+V7 -> EHDSPatient.identifier | S7: | | U7: EHDSPatient2 | V7: =_xlfn.IFNA(VLOOKUP($U7, XtEHR!A:F,2,FALSE)&"."&TRIM(VLOOKUP($U7, XtEHR!A:F,3,FALSE)),"-") -> EHDSPatient.identifier | Z7: Patient1 | AA7: =IF(LEN(Z7)>0,_xlfn.XLOOKUP(Z7,FHIR!A:A,FHIR!E:E),"") -> Patient.identifier
B8: PatientModule | D8: PatientModule | E8: Issuer of Patient ID Qualifiers Sequence | F8: Universal Entity ID | G8: Universal Entity ID | M8: | | N8: =D8&IF(LEN(E8)>0,"-","")&E8&IF(LEN(F8)>0,"-","")&F8&IF(LEN(G8)>0,"-","")&G8&IF(LEN(H8)>0,"-","")&H8 -> PatientModule-Issuer of Patient ID Qualifiers Sequence-Universal Entity ID-Universal Entity ID | O8: | | P8: =+AA8 -> Patient.identifier | Q8: | | R8: =+V8 -> EHDSPatient.identifier | S8: | | U8: EHDSPatient2 | V8: =_xlfn.IFNA(VLOOKUP($U8, XtEHR!A:F,2,FALSE)&"."&TRIM(VLOOKUP($U8, XtEHR!A:F,3,FALSE)),"-") -> EHDSPatient.identifier | Z8: Patient1 | AA8: =IF(LEN(Z8)>0,_xlfn.XLOOKUP(Z8,FHIR!A:A,FHIR!E:E),"") -> Patient.identifier
B9: PatientModule | D9: PatientModule | E9: Issuer of Patient ID Qualifiers Sequence | F9: Universal Entity ID Type | G9: Universal Entity ID Type | M9: | | N9: =D9&IF(LEN(E9)>0,"-","")&E9&IF(LEN(F9)>0,"-","")&F9&IF(LEN(G9)>0,"-","")&G9&IF(LEN(H9)>0,"-","")&H9 -> PatientModule-Issuer of Patient ID Qualifiers Sequence-Universal Entity ID Type-Universal Entity ID Type | O9: | | P9: =+AA9 -> Patient.identifier | Q9: | | R9: =+V9 -> EHDSPatient.identifier | S9: | | U9: EHDSPatient2 | V9: =_xlfn.IFNA(VLOOKUP($U9, XtEHR!A:F,2,FALSE)&"."&TRIM(VLOOKUP($U9, XtEHR!A:F,3,FALSE)),"-") -> EHDSPatient.identifier | Z9: Patient1 | AA9: =IF(LEN(Z9)>0,_xlfn.XLOOKUP(Z9,FHIR!A:A,FHIR!E:E),"") -> Patient.identifier | AD9: value (urn)
B10: PatientModule | D10: PatientModule | E10: Issuer of Patient ID Qualifiers Sequence | F10: Type of Patient ID | G10: Type of Patient ID | M10: | | N10: =D10&IF(LEN(E10)>0,"-","")&E10&IF(LEN(F10)>0,"-","")&F10&IF(LEN(G10)>0,"-","")&G10&IF(LEN(H10)>0,"-","")&H10 -> PatientModule-Issuer of Patient ID Qualifiers Sequence-Type of Patient ID-Type of Patient ID | O10: | | P10: =+AA10 -> Patient.identifier | Q10: | | R10: =+V10 -> EHDSPatient.identifier | S10: | | U10: EHDSPatient2 | V10: =_xlfn.IFNA(VLOOKUP($U10, XtEHR!A:F,2,FALSE)&"."&TRIM(VLOOKUP($U10, XtEHR!A:F,3,FALSE)),"-") -> EHDSPatient.identifier | Z10: Patient1 | AA10: =IF(LEN(Z10)>0,_xlfn.XLOOKUP(Z10,FHIR!A:A,FHIR!E:E),"") -> Patient.identifier
B11: PatientModule | D11: PatientModule | E11: Patient's Birth Date​ | J11: 1 | M11: | | N11: =D11&IF(LEN(E11)>0,"-","")&E11&IF(LEN(F11)>0,"-","")&F11&IF(LEN(G11)>0,"-","")&G11&IF(LEN(H11)>0,"-","")&H11 -> PatientModule-Patient's Birth Date​ | O11: | | P11: =+AA11 -> Patient.birthDate | Q11: | | R11: =+V11 -> EHDSPatient.dateOfBirth | S11: | | U11: EHDSPatient4 | V11: =_xlfn.IFNA(VLOOKUP($U11, XtEHR!A:F,2,FALSE)&"."&TRIM(VLOOKUP($U11, XtEHR!A:F,3,FALSE)),"-") -> EHDSPatient.dateOfBirth | Z11: Patient3 | AA11: =IF(LEN(Z11)>0,_xlfn.XLOOKUP(Z11,FHIR!A:A,FHIR!E:E),"") -> Patient.birthDate
B12: PatientModule | D12: PatientModule | E12: Patient's Sex​ | J12: 1 | M12: | | N12: =D12&IF(LEN(E12)>0,"-","")&E12&IF(LEN(F12)>0,"-","")&F12&IF(LEN(G12)>0,"-","")&G12&IF(LEN(H12)>0,"-","")&H12 -> PatientModule-Patient's Sex​ | O12: | | P12: =+AA12 -> Patient.gender | Q12: | | R12: =+V12 -> EHDSPatient.administrativeGender | S12: | | U12: EHDSPatient7 | V12: =_xlfn.IFNA(VLOOKUP($U12, XtEHR!A:F,2,FALSE)&"."&TRIM(VLOOKUP($U12, XtEHR!A:F,3,FALSE)),"-") -> EHDSPatient.administrativeGender | Z12: Patient6 | AA12: =IF(LEN(Z12)>0,_xlfn.XLOOKUP(Z12,FHIR!A:A,FHIR!E:E),"") -> Patient.gender
B13: PatientModule | D13: PatientModule | E13: Patient Comments | M13: | | N13: =D13&IF(LEN(E13)>0,"-","")&E13&IF(LEN(F13)>0,"-","")&F13&IF(LEN(G13)>0,"-","")&G13&IF(LEN(H13)>0,"-","")&H13 -> PatientModule-Patient Comments | O13: | | P13: =+AA13 | Q13: | | R13: =+V13 -> - | S13: | | V13: =_xlfn.IFNA(VLOOKUP($U13, XtEHR!A:F,2,FALSE)&"."&TRIM(VLOOKUP($U13, XtEHR!A:F,3,FALSE)),"-") -> - | AA13: =IF(LEN(Z13)>0,_xlfn.XLOOKUP(Z13,FHIR!A:A,FHIR!E:E),"")
B14: PatientModule | D14: PatientModule | E14: Other Patient IDs Sequence | M14: | | N14: =D14&IF(LEN(E14)>0,"-","")&E14&IF(LEN(F14)>0,"-","")&F14&IF(LEN(G14)>0,"-","")&G14&IF(LEN(H14)>0,"-","")&H14 -> PatientModule-Other Patient IDs Sequence | O14: | | P14: =+AA14 -> Patient.identifier | Q14: | | R14: =+V14 -> EHDSPatient.identifier | S14: | | U14: EHDSPatient2 | V14: =_xlfn.IFNA(VLOOKUP($U14, XtEHR!A:F,2,FALSE)&"."&TRIM(VLOOKUP($U14, XtEHR!A:F,3,FALSE)),"-") -> EHDSPatient.identifier | Z14: Patient1 | AA14: =IF(LEN(Z14)>0,_xlfn.XLOOKUP(Z14,FHIR!A:A,FHIR!E:E),"") -> Patient.identifier
B15: PatientModule | D15: PatientModule | E15: Other Patient IDs Sequence | F15: Patient ID | M15: | | N15: =D15&IF(LEN(E15)>0,"-","")&E15&IF(LEN(F15)>0,"-","")&F15&IF(LEN(G15)>0,"-","")&G15&IF(LEN(H15)>0,"-","")&H15 -> PatientModule-Other Patient IDs Sequence-Patient ID | O15: | | P15: =+AA15 -> Patient.identifier | Q15: | | R15: =+V15 -> EHDSPatient.identifier | S15: | | U15: EHDSPatient2 | V15: =_xlfn.IFNA(VLOOKUP($U15, XtEHR!A:F,2,FALSE)&"."&TRIM(VLOOKUP($U15, XtEHR!A:F,3,FALSE)),"-") -> EHDSPatient.identifier | Z15: Patient1 | AA15: =IF(LEN(Z15)>0,_xlfn.XLOOKUP(Z15,FHIR!A:A,FHIR!E:E),"") -> Patient.identifier | AD15: value
B16: PatientModule | D16: PatientModule | E16: Other Patient IDs Sequence | F16: Issuer of Patient ID | K16: O+ | M16: | | N16: =D16&IF(LEN(E16)>0,"-","")&E16&IF(LEN(F16)>0,"-","")&F16&IF(LEN(G16)>0,"-","")&G16&IF(LEN(H16)>0,"-","")&H16 -> PatientModule-Other Patient IDs Sequence-Issuer of Patient ID | O16: | | P16: =+AA16 -> Patient.identifier | Q16: | | R16: =+V16 -> EHDSPatient.identifier | S16: | | U16: EHDSPatient2 | V16: =_xlfn.IFNA(VLOOKUP($U16, XtEHR!A:F,2,FALSE)&"."&TRIM(VLOOKUP($U16, XtEHR!A:F,3,FALSE)),"-") -> EHDSPatient.identifier | Z16: Patient1 | AA16: =IF(LEN(Z16)>0,_xlfn.XLOOKUP(Z16,FHIR!A:A,FHIR!E:E),"") -> Patient.identifier | AD16: system
B17: PatientModule | D17: PatientModule | E17: Other Patient IDs Sequence | F17: Issuer of Patient ID Qualifiers Sequence | K17: R+ | M17: | | N17: =D17&IF(LEN(E17)>0,"-","")&E17&IF(LEN(F17)>0,"-","")&F17&IF(LEN(G17)>0,"-","")&G17&IF(LEN(H17)>0,"-","")&H17 -> PatientModule-Other Patient IDs Sequence-Issuer of Patient ID Qualifiers Sequence | O17: | | P17: =+AA17 -> Patient.identifier | Q17: | | R17: =+V17 -> EHDSPatient.identifier | S17: | | U17: EHDSPatient2 | V17: =_xlfn.IFNA(VLOOKUP($U17, XtEHR!A:F,2,FALSE)&"."&TRIM(VLOOKUP($U17, XtEHR!A:F,3,FALSE)),"-") -> EHDSPatient.identifier | Z17: Patient1 | AA17: =IF(LEN(Z17)>0,_xlfn.XLOOKUP(Z17,FHIR!A:A,FHIR!E:E),"") -> Patient.identifier
B18: PatientModule | D18: PatientModule | E18: Other Patient IDs Sequence | F18: Issuer of Patient ID Qualifiers Sequence | G18: Universal Entity ID | K18: R+ | M18: | | N18: =D18&IF(LEN(E18)>0,"-","")&E18&IF(LEN(F18)>0,"-","")&F18&IF(LEN(G18)>0,"-","")&G18&IF(LEN(H18)>0,"-","")&H18 -> PatientModule-Other Patient IDs Sequence-Issuer of Patient ID Qualifiers Sequence-Universal Entity ID | O18: | | P18: =+AA18 -> Patient.identifier | Q18: | | R18: =+V18 -> EHDSPatient.identifier | S18: | | U18: EHDSPatient2 | V18: =_xlfn.IFNA(VLOOKUP($U18, XtEHR!A:F,2,FALSE)&"."&TRIM(VLOOKUP($U18, XtEHR!A:F,3,FALSE)),"-") -> EHDSPatient.identifier | Z18: Patient1 | AA18: =IF(LEN(Z18)>0,_xlfn.XLOOKUP(Z18,FHIR!A:A,FHIR!E:E),"") -> Patient.identifier | AD18: system
B19: PatientModule | D19: PatientModule | E19: Other Patient IDs Sequence | F19: Issuer of Patient ID Qualifiers Sequence | G19: Universal Entity ID Type | K19: RC+ | M19: | | N19: =D19&IF(LEN(E19)>0,"-","")&E19&IF(LEN(F19)>0,"-","")&F19&IF(LEN(G19)>0,"-","")&G19&IF(LEN(H19)>0,"-","")&H19 -> PatientModule-Other Patient IDs Sequence-Issuer of Patient ID Qualifiers Sequence-Universal Entity ID Type | O19: | | P19: =+AA19 -> Patient.identifier | Q19: | | R19: =+V19 -> EHDSPatient.identifier | S19: | | U19: EHDSPatient2 | V19: =_xlfn.IFNA(VLOOKUP($U19, XtEHR!A:F,2,FALSE)&"."&TRIM(VLOOKUP($U19, XtEHR!A:F,3,FALSE)),"-") -> EHDSPatient.identifier | Z19: Patient1 | AA19: =IF(LEN(Z19)>0,_xlfn.XLOOKUP(Z19,FHIR!A:A,FHIR!E:E),"") -> Patient.identifier | AD19: value (urn)
B20: PatientModule | D20: PatientModule | E20: Other Patient IDs Sequence | F20: Issuer of Patient ID Qualifiers Sequence | G20: Type of Patient ID | M20: | | N20: =D20&IF(LEN(E20)>0,"-","")&E20&IF(LEN(F20)>0,"-","")&F20&IF(LEN(G20)>0,"-","")&G20&IF(LEN(H20)>0,"-","")&H20 -> PatientModule-Other Patient IDs Sequence-Issuer of Patient ID Qualifiers Sequence-Type of Patient ID | O20: | | P20: =+AA20 -> Patient.identifier | Q20: | | R20: =+V20 -> EHDSPatient.identifier | S20: | | U20: EHDSPatient2 | V20: =_xlfn.IFNA(VLOOKUP($U20, XtEHR!A:F,2,FALSE)&"."&TRIM(VLOOKUP($U20, XtEHR!A:F,3,FALSE)),"-") -> EHDSPatient.identifier | Z20: Patient1 | AA20: =IF(LEN(Z20)>0,_xlfn.XLOOKUP(Z20,FHIR!A:A,FHIR!E:E),"") -> Patient.identifier
B21: PatientModule | D21: PatientModule | E21: PatientSpeciesDescription | I21: When not human | J21: 1C | M21: | | N21: =D21&IF(LEN(E21)>0,"-","")&E21&IF(LEN(F21)>0,"-","")&F21&IF(LEN(G21)>0,"-","")&G21&IF(LEN(H21)>0,"-","")&H21 -> PatientModule-PatientSpeciesDescription | O21: | | P21: =+AA21 -> Patient.extension[patient-animal]extension[species] | Q21: | | R21: =+V21 -> - | S21: | | V21: =_xlfn.IFNA(VLOOKUP($U21, XtEHR!A:F,2,FALSE)&"."&TRIM(VLOOKUP($U21, XtEHR!A:F,3,FALSE)),"-") -> - | Z21: Patient10 | AA21: =IF(LEN(Z21)>0,_xlfn.XLOOKUP(Z21,FHIR!A:A,FHIR!E:E),"") -> Patient.extension[patient-animal]extension[species]
B22: PatientModule | D22: PatientModule | E22: Patient Species Code Sequence | I22: When not human | J22: 1C | M22: | | N22: =D22&IF(LEN(E22)>0,"-","")&E22&IF(LEN(F22)>0,"-","")&F22&IF(LEN(G22)>0,"-","")&G22&IF(LEN(H22)>0,"-","")&H22 -> PatientModule-Patient Species Code Sequence | O22: | | P22: =+AA22 -> Patient.extension[patient-animal]extension[species] | Q22: | | R22: =+V22 -> - | S22: | | V22: =_xlfn.IFNA(VLOOKUP($U22, XtEHR!A:F,2,FALSE)&"."&TRIM(VLOOKUP($U22, XtEHR!A:F,3,FALSE)),"-") -> - | Z22: Patient10 | AA22: =IF(LEN(Z22)>0,_xlfn.XLOOKUP(Z22,FHIR!A:A,FHIR!E:E),"") -> Patient.extension[patient-animal]extension[species]
B23: PatientModule | D23: PatientModule | E23: Patient Breed description | I23: When not human | M23: | | N23: =D23&IF(LEN(E23)>0,"-","")&E23&IF(LEN(F23)>0,"-","")&F23&IF(LEN(G23)>0,"-","")&G23&IF(LEN(H23)>0,"-","")&H23 -> PatientModule-Patient Breed description | O23: | | P23: =+AA23 -> Patient.extension[patient-animal].extension[breed] | Q23: | | R23: =+V23 -> - | S23: | | V23: =_xlfn.IFNA(VLOOKUP($U23, XtEHR!A:F,2,FALSE)&"."&TRIM(VLOOKUP($U23, XtEHR!A:F,3,FALSE)),"-") -> - | Z23: Patient11 | AA23: =IF(LEN(Z23)>0,_xlfn.XLOOKUP(Z23,FHIR!A:A,FHIR!E:E),"") -> Patient.extension[patient-animal].extension[breed]
B24: PatientModule | D24: PatientModule | E24: Patient Breed Code Sequence | I24: When not human | M24: | | N24: =D24&IF(LEN(E24)>0,"-","")&E24&IF(LEN(F24)>0,"-","")&F24&IF(LEN(G24)>0,"-","")&G24&IF(LEN(H24)>0,"-","")&H24 -> PatientModule-Patient Breed Code Sequence | O24: | | P24: =+AA24 -> Patient.extension[patient-animal].extension[breed] | Q24: | | R24: =+V24 -> - | S24: | | V24: =_xlfn.IFNA(VLOOKUP($U24, XtEHR!A:F,2,FALSE)&"."&TRIM(VLOOKUP($U24, XtEHR!A:F,3,FALSE)),"-") -> - | Z24: Patient11 | AA24: =IF(LEN(Z24)>0,_xlfn.XLOOKUP(Z24,FHIR!A:A,FHIR!E:E),"") -> Patient.extension[patient-animal].extension[breed]
M25: | | N25: =D25&IF(LEN(E25)>0,"-","")&E25&IF(LEN(F25)>0,"-","")&F25&IF(LEN(G25)>0,"-","")&G25&IF(LEN(H25)>0,"-","")&H25 | O25: | | P25: =+AA25 | Q25: | | R25: =+V25 -> - | S25: | | V25: =_xlfn.IFNA(VLOOKUP($U25, XtEHR!A:F,2,FALSE)&"."&TRIM(VLOOKUP($U25, XtEHR!A:F,3,FALSE)),"-") -> - | AA25: =IF(LEN(Z25)>0,_xlfn.XLOOKUP(Z25,FHIR!A:A,FHIR!E:E),"")
A26: Study | B26: General Study | C26: C.7.2.1 | D26: General Study | E26: StudyInstanceUID | J26: 1 | M26: | | N26: =D26&IF(LEN(E26)>0,"-","")&E26&IF(LEN(F26)>0,"-","")&F26&IF(LEN(G26)>0,"-","")&G26&IF(LEN(H26)>0,"-","")&H26 -> General Study-StudyInstanceUID | O26: | | P26: =+AA26 -> ImagingStudy.identifier[studyInstanceUid] | Q26: | | R26: =+V26 -> EHDSImagingStudy.header.identifier | S26: | | U26: EHDSImagingStudy4 | V26: =_xlfn.IFNA(VLOOKUP($U26, XtEHR!A:F,2,FALSE)&"."&TRIM(VLOOKUP($U26, XtEHR!A:F,3,FALSE)),"-") -> EHDSImagingStudy.header.identifier | Z26: ImagingStudy3 | AA26: =IF(LEN(Z26)>0,_xlfn.XLOOKUP(Z26,FHIR!A:A,FHIR!E:E),"") -> ImagingStudy.identifier[studyInstanceUid] | AD26: value
D27: General Study | E27: StudyID | J27: 2 | M27: | | N27: =D27&IF(LEN(E27)>0,"-","")&E27&IF(LEN(F27)>0,"-","")&F27&IF(LEN(G27)>0,"-","")&G27&IF(LEN(H27)>0,"-","")&H27 -> General Study-StudyID | O27: | | P27: =+AA27 -> ImagingStudy.identifier[studyUid] | Q27: | | R27: =+V27 -> - | S27: | | V27: =_xlfn.IFNA(VLOOKUP($U27, XtEHR!A:F,2,FALSE)&"."&TRIM(VLOOKUP($U27, XtEHR!A:F,3,FALSE)),"-") -> - | Z27: ImagingStudy3.1 | AA27: =IF(LEN(Z27)>0,_xlfn.XLOOKUP(Z27,FHIR!A:A,FHIR!E:E),"") -> ImagingStudy.identifier[studyUid] | AD27: value
D28: General Study | E28: Modality | I28: SR | M28: | | N28: =D28&IF(LEN(E28)>0,"-","")&E28&IF(LEN(F28)>0,"-","")&F28&IF(LEN(G28)>0,"-","")&G28&IF(LEN(H28)>0,"-","")&H28 -> General Study-Modality | O28: | | P28: =+AA28 -> ImagingStudy.modality | Q28: | | R28: =+V28 -> EHDSImagingStudy.modality | S28: | | U28: EHDSImagingStudy11 | V28: =_xlfn.IFNA(VLOOKUP($U28, XtEHR!A:F,2,FALSE)&"."&TRIM(VLOOKUP($U28, XtEHR!A:F,3,FALSE)),"-") -> EHDSImagingStudy.modality | Z28: ImagingStudy6 | AA28: =IF(LEN(Z28)>0,_xlfn.XLOOKUP(Z28,FHIR!A:A,FHIR!E:E),"") -> ImagingStudy.modality
D29: General Study | E29: StudyDate | J29: 2 | K29: R+ | M29: | | N29: =D29&IF(LEN(E29)>0,"-","")&E29&IF(LEN(F29)>0,"-","")&F29&IF(LEN(G29)>0,"-","")&G29&IF(LEN(H29)>0,"-","")&H29 -> General Study-StudyDate | O29: | | P29: =+AA29 -> ImagingStudy.started | Q29: | | R29: =+V29 -> EHDSImagingStudy.started | S29: | | U29: EHDSImagingStudy14 | V29: =_xlfn.IFNA(VLOOKUP($U29, XtEHR!A:F,2,FALSE)&"."&TRIM(VLOOKUP($U29, XtEHR!A:F,3,FALSE)),"-") -> EHDSImagingStudy.started | Z29: ImagingStudy10 | AA29: =IF(LEN(Z29)>0,_xlfn.XLOOKUP(Z29,FHIR!A:A,FHIR!E:E),"") -> ImagingStudy.started
D30: General Study | E30: StudyTime | J30: 2 | K30: R+ | M30: | | N30: =D30&IF(LEN(E30)>0,"-","")&E30&IF(LEN(F30)>0,"-","")&F30&IF(LEN(G30)>0,"-","")&G30&IF(LEN(H30)>0,"-","")&H30 -> General Study-StudyTime | O30: | | P30: =+AA30 -> ImagingStudy.started | Q30: | | R30: =+V30 -> EHDSImagingStudy.started | S30: | | U30: EHDSImagingStudy14 | V30: =_xlfn.IFNA(VLOOKUP($U30, XtEHR!A:F,2,FALSE)&"."&TRIM(VLOOKUP($U30, XtEHR!A:F,3,FALSE)),"-") -> EHDSImagingStudy.started | Z30: ImagingStudy10 | AA30: =IF(LEN(Z30)>0,_xlfn.XLOOKUP(Z30,FHIR!A:A,FHIR!E:E),"") -> ImagingStudy.started
D31: General Study | E31: AccessionNumber | J31: 2 | K31: O+ | M31: | | N31: =D31&IF(LEN(E31)>0,"-","")&E31&IF(LEN(F31)>0,"-","")&F31&IF(LEN(G31)>0,"-","")&G31&IF(LEN(H31)>0,"-","")&H31 -> General Study-AccessionNumber | O31: | | P31: =+AA31 -> ServiceRequest-Order.identifier | Q31: | | R31: =+V31 -> EHDSServiceRequest.header.identifier | S31: | | U31: EHDSServiceRequest4 | V31: =_xlfn.IFNA(VLOOKUP($U31, XtEHR!A:F,2,FALSE)&"."&TRIM(VLOOKUP($U31, XtEHR!A:F,3,FALSE)),"-") -> EHDSServiceRequest.header.identifier | Z31: Order2 | AA31: =IF(LEN(Z31)>0,_xlfn.XLOOKUP(Z31,FHIR!A:A,FHIR!E:E),"") -> ServiceRequest-Order.identifier | AD31: value
D32: General Study | E32: IssuerOfAccessionNumberSequence | K32: RC+ | M32: | | N32: =D32&IF(LEN(E32)>0,"-","")&E32&IF(LEN(F32)>0,"-","")&F32&IF(LEN(G32)>0,"-","")&G32&IF(LEN(H32)>0,"-","")&H32 -> General Study-IssuerOfAccessionNumberSequence | O32: | | P32: =+AA32 -> ServiceRequest-Order.identifier | Q32: | | R32: =+V32 -> EHDSServiceRequest.header.identifier | S32: | | U32: EHDSServiceRequest4 | V32: =_xlfn.IFNA(VLOOKUP($U32, XtEHR!A:F,2,FALSE)&"."&TRIM(VLOOKUP($U32, XtEHR!A:F,3,FALSE)),"-") -> EHDSServiceRequest.header.identifier | Z32: Order2 | AA32: =IF(LEN(Z32)>0,_xlfn.XLOOKUP(Z32,FHIR!A:A,FHIR!E:E),"") -> ServiceRequest-Order.identifier
D33: General Study | E33: IssuerOfAccessionNumberSequence | F33: UniversalEntityIdType | M33: | | N33: =D33&IF(LEN(E33)>0,"-","")&E33&IF(LEN(F33)>0,"-","")&F33&IF(LEN(G33)>0,"-","")&G33&IF(LEN(H33)>0,"-","")&H33 -> General Study-IssuerOfAccessionNumberSequence-UniversalEntityIdType | O33: | | P33: =+AA33 -> ServiceRequest-Order.identifier | Q33: | | R33: =+V33 -> EHDSServiceRequest.header.identifier | S33: | | U33: EHDSServiceRequest4 | V33: =_xlfn.IFNA(VLOOKUP($U33, XtEHR!A:F,2,FALSE)&"."&TRIM(VLOOKUP($U33, XtEHR!A:F,3,FALSE)),"-") -> EHDSServiceRequest.header.identifier | Z33: Order2 | AA33: =IF(LEN(Z33)>0,_xlfn.XLOOKUP(Z33,FHIR!A:A,FHIR!E:E),"") -> ServiceRequest-Order.identifier | AD33: type
D34: General Study | E34: IssuerOfAccessionNumberSequence | F34: UniversalEntityId | M34: | | N34: =D34&IF(LEN(E34)>0,"-","")&E34&IF(LEN(F34)>0,"-","")&F34&IF(LEN(G34)>0,"-","")&G34&IF(LEN(H34)>0,"-","")&H34 -> General Study-IssuerOfAccessionNumberSequence-UniversalEntityId | O34: | | P34: =+AA34 -> ServiceRequest-Order.identifier | Q34: | | R34: =+V34 -> EHDSServiceRequest.header.identifier | S34: | | U34: EHDSServiceRequest4 | V34: =_xlfn.IFNA(VLOOKUP($U34, XtEHR!A:F,2,FALSE)&"."&TRIM(VLOOKUP($U34, XtEHR!A:F,3,FALSE)),"-") -> EHDSServiceRequest.header.identifier | Z34: Order2 | AA34: =IF(LEN(Z34)>0,_xlfn.XLOOKUP(Z34,FHIR!A:A,FHIR!E:E),"") -> ServiceRequest-Order.identifier | AD34: ?
D35: General Study | E35: Study Description | F35: Study Description | M35: | | N35: =D35&IF(LEN(E35)>0,"-","")&E35&IF(LEN(F35)>0,"-","")&F35&IF(LEN(G35)>0,"-","")&G35&IF(LEN(H35)>0,"-","")&H35 -> General Study-Study Description-Study Description | O35: | | P35: =+AA35 -> ImagingStudy.description | Q35: | | R35: =+V35 -> EHDSServiceRequest.header.identifier | S35: | | U35: EHDSServiceRequest4 | V35: =_xlfn.IFNA(VLOOKUP($U35, XtEHR!A:F,2,FALSE)&"."&TRIM(VLOOKUP($U35, XtEHR!A:F,3,FALSE)),"-") -> EHDSServiceRequest.header.identifier | Z35: ImagingStudy23 | AA35: =IF(LEN(Z35)>0,_xlfn.XLOOKUP(Z35,FHIR!A:A,FHIR!E:E),"") -> ImagingStudy.description
D36: General Study | E36: RefferringPhusician's Name | J36: 2 | M36: | | N36: =D36&IF(LEN(E36)>0,"-","")&E36&IF(LEN(F36)>0,"-","")&F36&IF(LEN(G36)>0,"-","")&G36&IF(LEN(H36)>0,"-","")&H36 -> General Study-RefferringPhusician's Name | O36: | | P36: =+AA36 -> ServiceRequest-Order.reasonReference | Q36: | | R36: =+V36 -> - | S36: | | V36: =_xlfn.IFNA(VLOOKUP($U36, XtEHR!A:F,2,FALSE)&"."&TRIM(VLOOKUP($U36, XtEHR!A:F,3,FALSE)),"-") -> - | Z36: Order13 | AA36: =IF(LEN(Z36)>0,_xlfn.XLOOKUP(Z36,FHIR!A:A,FHIR!E:E),"") -> ServiceRequest-Order.reasonReference | AD36: -> | AE36: ServiceRequest-RequestedProcedure | AF36: requester | AG36: -> | AH36: Practitioner | AI36: name
D37: General Study | E37: Reason For Performed Procedure Code Sequence | J37: 3 | M37: | | N37: =D37&IF(LEN(E37)>0,"-","")&E37&IF(LEN(F37)>0,"-","")&F37&IF(LEN(G37)>0,"-","")&G37&IF(LEN(H37)>0,"-","")&H37 -> General Study-Reason For Performed Procedure Code Sequence | O37: | | P37: =+AA37 | Q37: | | R37: =+V37 -> - | S37: | | V37: =_xlfn.IFNA(VLOOKUP($U37, XtEHR!A:F,2,FALSE)&"."&TRIM(VLOOKUP($U37, XtEHR!A:F,3,FALSE)),"-") -> - | AA37: =IF(LEN(Z37)>0,_xlfn.XLOOKUP(Z37,FHIR!A:A,FHIR!E:E),"")
M38: | | O38: | | Q38: | | S38: | | AA38: =IF(LEN(Z38)>0,_xlfn.XLOOKUP(Z38,FHIR!A:A,FHIR!E:E),"")
A39: Equipment | B39: General Equipment | C39: C.7.5.1 | D39: General Equipment | E39: Manufacturer | I39: Configuration - KOS author | M39: | | N39: =D39&IF(LEN(E39)>0,"-","")&E39&IF(LEN(F39)>0,"-","")&F39&IF(LEN(G39)>0,"-","")&G39&IF(LEN(H39)>0,"-","")&H39 -> General Equipment-Manufacturer | O39: | | P39: =+AA39 -> MhDDocumentReference.author[madoDevice] | Q39: | | R39: =+V39 -> EHDSImagingStudy.header.author[EHDSDevice] | S39: | | U39: EHDSImagingStudy7 | V39: =_xlfn.IFNA(VLOOKUP($U39, XtEHR!A:F,2,FALSE)&"."&TRIM(VLOOKUP($U39, XtEHR!A:F,3,FALSE)),"-") -> EHDSImagingStudy.header.author[EHDSDevice] | Z39: MhdDocRef8 | AA39: =IF(LEN(Z39)>0,_xlfn.XLOOKUP(Z39,FHIR!A:A,FHIR!E:E),"") -> MhDDocumentReference.author[madoDevice] | AD39: -> | AE39: Device-Author | AF39: manufacturer
D40: General Equipment | E40: Institution Name | I40: Configuration - KOS author | M40: | | N40: =D40&IF(LEN(E40)>0,"-","")&E40&IF(LEN(F40)>0,"-","")&F40&IF(LEN(G40)>0,"-","")&G40&IF(LEN(H40)>0,"-","")&H40 -> General Equipment-Institution Name | O40: | | P40: =+AA40 -> MhDDocumentReference.author[organization] | Q40: | | R40: =+V40 -> EHDSImagingStudy.header.author[EHDSOrganization] | S40: | | U40: EHDSImagingStudy6 | V40: =_xlfn.IFNA(VLOOKUP($U40, XtEHR!A:F,2,FALSE)&"."&TRIM(VLOOKUP($U40, XtEHR!A:F,3,FALSE)),"-") -> EHDSImagingStudy.header.author[EHDSOrganization] | Z40: MhdDocRef9 | AA40: =IF(LEN(Z40)>0,_xlfn.XLOOKUP(Z40,FHIR!A:A,FHIR!E:E),"") -> MhDDocumentReference.author[organization] | AD40: -> | AE40: Device-Author | AF40: owner | AG40: -> | AH40: Organization | AI40: name
...

Sheet KOS SR
B1: NL | C1: Rel with Parent | D1: VT | E1: Concept Name | F1: VM | G1: Req Type | H1: Condition | J1: Value Set Constraint | M1: | | N1: KOS-SR | O1: | | P1: FHIR | Q1: | | R1: XtEHR | S1: | | V1: FHIR | X1: XtEHR
M2: | | N2: --------- | O2: | | P2: --------- | Q2: | | R2: ---------
A3: TID2010 | B3: 1 | E3: CONTAINER | F3: DCID 7010 “Key Object Selection Document Title” | G3: 1 | H3: M | K3: Root node | M3: | | N3: v | O3: | | P3: =T(W3) | Q3: | | R3: =T(Y3) | S3: | | X3: =IF(LEN(V3)>0,_xlfn.XLOOKUP(V3,FHIR!A:A,FHIR!M:M,""),"") | Y3: =_xlfn.XLOOKUP(X3,XtEHR!A:A,XtEHR!I:I,"")
A4: TID2010 | B4: 2 | C4: > | D4: HAS CONCEPT MOD | E4: CODE | F4: EV (113011, DCM, "Document Title Modifier") | G4: 1-n | H4: U | M4: | | N4: ="SR-"&A4&":"&B4&F4 -> SR-TID2010:2EV (113011, DCM, "Document Title Modifier") | O4: | | P4: =T(W4) | Q4: | | R4: =T(Y4) | S4: | | X4: =IF(LEN(V4)>0,_xlfn.XLOOKUP(V4,FHIR!A:A,FHIR!M:M,""),"") | Y4: =_xlfn.XLOOKUP(X4,XtEHR!A:A,XtEHR!I:I,"")
A5: TID2010 | B5: 3 | C5: > | D5: HAS CONCEPT MOD | E5: CODE | F5: EV (113011, DCM, "Document Title Modifier") | G5: 1 | H5: UC | J5: IF Row 1 Concept Name = (113001, DCM, "Rejected for Quality Reasons") or (113010, DCM, "Quality Issue") | K5: DCID 7011 “Rejected for Quality Reason” | M5: | | N5: ="SR-"&A5&":"&B5&F5 -> SR-TID2010:3EV (113011, DCM, "Document Title Modifier") | O5: | | P5: =T(W5) | Q5: | | R5: =T(Y5) | S5: | | X5: =IF(LEN(V5)>0,_xlfn.XLOOKUP(V5,FHIR!A:A,FHIR!M:M,""),"") | Y5: =_xlfn.XLOOKUP(X5,XtEHR!A:A,XtEHR!I:I,"")
A6: TID2010 | B6: 4 | C6: > | D6: HAS CONCEPT MOD | E6: CODE | F6: EV (113011, DCM, "Document Title Modifier") | G6: 1 | H6: MC | J6: IF Row 1 Concept Name = (113013, DCM, "Best In Set") | K6: DCID 7012 “Best in Set” | M6: | | N6: ="SR-"&A6&":"&B6&F6 -> SR-TID2010:4EV (113011, DCM, "Document Title Modifier") | O6: | | P6: =T(W6) | Q6: | | R6: =T(Y6) | S6: | | X6: =IF(LEN(V6)>0,_xlfn.XLOOKUP(V6,FHIR!A:A,FHIR!M:M,""),"") | Y6: =_xlfn.XLOOKUP(X6,XtEHR!A:A,XtEHR!I:I,"")
A7: TID2010 | B7: 5 | C7: > | D7: HAS CONCEPT MOD | E7: INCLUDE | F7: DTID 1204 “Language of Content Item and Descendants” | G7: 1 | H7: U | M7: | | N7: ="SR-"&A7&":"&B7&F7 -> SR-TID2010:5DTID 1204 “Language of Content Item and Descendants” | O7: | | P7: =T(W7) | Q7: | | R7: =T(Y7) | S7: | | X7: =IF(LEN(V7)>0,_xlfn.XLOOKUP(V7,FHIR!A:A,FHIR!M:M,""),"") | Y7: =_xlfn.XLOOKUP(X7,XtEHR!A:A,XtEHR!I:I,"")
A8: TID2010 | B8: 6 | C8: > | D8: HAS OBS CONTEXT | E8: INCLUDE | F8: DTID 1002 “Observer Context” | G8: 1-n | H8: U | M8: | | N8: ="SR-"&A8&":"&B8&F8 -> SR-TID2010:6DTID 1002 “Observer Context” | O8: | | P8: =T(W8) | Q8: | | R8: =T(Y8) | S8: | | X8: =IF(LEN(V8)>0,_xlfn.XLOOKUP(V8,FHIR!A:A,FHIR!M:M,""),"") | Y8: =_xlfn.XLOOKUP(X8,XtEHR!A:A,XtEHR!I:I,"")
A9: TID2010 | B9: 7 | C9: > | D9: CONTAINS | E9: TEXT | F9: EV (113012, DCM, "Key Object Description") | G9: 1 | H9: U | M9: | | N9: ="SR-"&A9&":"&B9&F9 -> SR-TID2010:7EV (113012, DCM, "Key Object Description") | O9: | | P9: =T(W9) | Q9: | | R9: =T(Y9) | S9: | | X9: =IF(LEN(V9)>0,_xlfn.XLOOKUP(V9,FHIR!A:A,FHIR!M:M,""),"") | Y9: =_xlfn.XLOOKUP(X9,XtEHR!A:A,XtEHR!I:I,"")
A10: TID2010 | B10: 8 | C10: > | D10: CONTAINS | E10: IMAGE | G10: 1-n | H10: MC | J10: At least one of Rows 8, 9 and 10 shall be present | L10: only one represantative instance | M10: | | N10: ="SR-"&A10&":"&B10&F10 -> SR-TID2010:8 | O10: | | P10: =T(W10) -> ImagingStudy.series.instance.extension[representative] | Q10: | | R10: =T(Y10) | S10: | | V10: ImagingStudy42 | W10: =_xlfn.XLOOKUP(V10,FHIR!A:A,FHIR!E:E) -> ImagingStudy.series.instance.extension[representative] | X10: - | Y10: =_xlfn.XLOOKUP(X10,XtEHR!A:A,XtEHR!I:I,"")
A11: TID2010 | B11: 9 | C11: > | D11: CONTAINS | E11: WAVEFORM | G11: 1-n | H11: MC | J11: At least one of Rows 8, 9 and 10 shall be present | L11: only one represantative instance | M11: | | N11: ="SR-"&A11&":"&B11&F11 -> SR-TID2010:9 | O11: | | P11: =T(W11) -> ImagingStudy.series.instance.extension[representative] | Q11: | | R11: =T(Y11) | S11: | | V11: ImagingStudy42 | W11: =_xlfn.XLOOKUP(V11,FHIR!A:A,FHIR!E:E) -> ImagingStudy.series.instance.extension[representative] | X11: - | Y11: =_xlfn.XLOOKUP(X11,XtEHR!A:A,XtEHR!I:I,"")
A12: TID2010 | B12: 10 | C12: > | D12: CONTAINS | E12: COMPOSITE | G12: 1-n | H12: MC | J12: At least one of Rows 8, 9 and 10 shall be present | L12: only one represantative instance | M12: | | N12: ="SR-"&A12&":"&B12&F12 -> SR-TID2010:10 | O12: | | P12: =T(W12) -> ImagingStudy.series.instance.extension[representative] | Q12: | | R12: =T(Y12) | S12: | | V12: ImagingStudy42 | W12: =_xlfn.XLOOKUP(V12,FHIR!A:A,FHIR!E:E) -> ImagingStudy.series.instance.extension[representative] | X12: - | Y12: =_xlfn.XLOOKUP(X12,XtEHR!A:A,XtEHR!I:I,"")
A13: TID2010 | B13: 11 | C13: > | D13: CONTAINS | E13: CONTAINER | F13: TID1600 (111028, DCM, "Image Library") | G13: 1 | M13: | | N13: ="SR-"&A13&":"&B13&F13 -> SR-TID2010:11TID1600 (111028, DCM, "Image Library") | O13: | | P13: =T(W13) -> -------- | Q13: | | R13: =T(Y13) | S13: | | W13: =_xlfn.XLOOKUP(V13,FHIR!A:A,FHIR!E:E) -> -------- | X13: =IF(LEN(V13)>0,_xlfn.XLOOKUP(V13,FHIR!A:A,FHIR!M:M,""),"") | Y13: =_xlfn.XLOOKUP(X13,XtEHR!A:A,XtEHR!I:I,"")
M14: | | N14: ="SR-"&A14&":"&B14&F14 -> SR-: | O14: | | P14: =T(W14) -> -------- | Q14: | | R14: =T(Y14) | S14: | | W14: =_xlfn.XLOOKUP(V14,FHIR!A:A,FHIR!E:E) -> -------- | X14: =IF(LEN(V14)>0,_xlfn.XLOOKUP(V14,FHIR!A:A,FHIR!M:M,""),"") | Y14: =_xlfn.XLOOKUP(X14,XtEHR!A:A,XtEHR!I:I,"")
A15: TID1600 | B15: NL | C15: Rel with Parent | D15: VT | E15: Concept Name | F15: VM | G15: Req Type | H15: Condition | J15: Value Set Constraint | M15: | | N15: ="SR-"&A15&":"&B15&F15 -> SR-TID1600:NLVM | O15: | | P15: =T(W15) -> -------- | Q15: | | R15: =T(Y15) | S15: | | W15: =_xlfn.XLOOKUP(V15,FHIR!A:A,FHIR!E:E) -> -------- | X15: =IF(LEN(V15)>0,_xlfn.XLOOKUP(V15,FHIR!A:A,FHIR!M:M,""),"") | Y15: =_xlfn.XLOOKUP(X15,XtEHR!A:A,XtEHR!I:I,"")
A16: TID1600 | B16: 1 | E16: CONTAINER | F16: EV (111028, DCM, "Image Library") | G16: 1 | H16: M | M16: | | N16: ="SR-"&A16&":"&B16&F16 -> SR-TID1600:1EV (111028, DCM, "Image Library") | O16: | | P16: =T(W16) -> -------- | Q16: | | R16: =T(Y16) | S16: | | W16: =_xlfn.XLOOKUP(V16,FHIR!A:A,FHIR!E:E) -> -------- | X16: =IF(LEN(V16)>0,_xlfn.XLOOKUP(V16,FHIR!A:A,FHIR!M:M,""),"") | Y16: =_xlfn.XLOOKUP(X16,XtEHR!A:A,XtEHR!I:I,"")
A17: TID1600 | B17: 2 | C17: > | D17: CONTAINS | E17: CONTAINER | F17: EV (126200, DCM, "Image Library Group") | G17: 1-n | H17: U | M17: | | N17: ="SR-"&A17&":"&B17&F17 -> SR-TID1600:2EV (126200, DCM, "Image Library Group") | O17: | | P17: =T(W17) -> -------- | Q17: | | R17: =T(Y17) | S17: | | W17: =_xlfn.XLOOKUP(V17,FHIR!A:A,FHIR!E:E) -> -------- | X17: =IF(LEN(V17)>0,_xlfn.XLOOKUP(V17,FHIR!A:A,FHIR!M:M,""),"") | Y17: =_xlfn.XLOOKUP(X17,XtEHR!A:A,XtEHR!I:I,"")
A18: TID1600 | B18: 3 | C18: >> | D18: HAS ACQ CONTEXT | E18: INCLUDE | F18: DTID 1602 “Image Library Entry Descriptors” | G18: 1 | H18: U | M18: | | N18: ="SR-"&A18&":"&B18&F18 -> SR-TID1600:3DTID 1602 “Image Library Entry Descriptors” | O18: | | P18: =T(W18) -> -------- | Q18: | | R18: =T(Y18) | S18: | | W18: =_xlfn.XLOOKUP(V18,FHIR!A:A,FHIR!E:E) -> -------- | X18: =IF(LEN(V18)>0,_xlfn.XLOOKUP(V18,FHIR!A:A,FHIR!M:M,""),"") | Y18: =_xlfn.XLOOKUP(X18,XtEHR!A:A,XtEHR!I:I,"")
A19: TID1600 | B19: 4 | C19: >> | D19: CONTAINS | E19: INCLUDE | F19: DTID 1601 “Image Library Entry” | G19: 1-n | H19: U | M19: | | N19: ="SR-"&A19&":"&B19&F19 -> SR-TID1600:4DTID 1601 “Image Library Entry” | O19: | | P19: =T(W19) -> -------- | Q19: | | R19: =T(Y19) | S19: | | W19: =_xlfn.XLOOKUP(V19,FHIR!A:A,FHIR!E:E) -> -------- | X19: =IF(LEN(V19)>0,_xlfn.XLOOKUP(V19,FHIR!A:A,FHIR!M:M,""),"") | Y19: =_xlfn.XLOOKUP(X19,XtEHR!A:A,XtEHR!I:I,"")
A20: TID1600 | C20: > | D20: HAS ACQ CONTEXT | E20: CODE | F20: EV (121139, DCM, "Modality") | G20: 1-n | H20: R+ | M20: | | N20: ="SR-"&A20&":"&B20&F20 -> SR-TID1600:EV (121139, DCM, "Modality") | O20: | | P20: =T(W20) -> ImagingStudy.modality | Q20: | | R20: =T(Y20) -> EHDSImagingStudy- modality | S20: | | V20: ImagingStudy6 | W20: =_xlfn.XLOOKUP(V20,FHIR!A:A,FHIR!E:E) -> ImagingStudy.modality | X20: =IF(LEN(V20)>0,_xlfn.XLOOKUP(V20,FHIR!A:A,FHIR!M:M,""),"") -> EHDSImagingStudy11 | Y20: =_xlfn.XLOOKUP(X20,XtEHR!A:A,XtEHR!I:I,"") -> EHDSImagingStudy- modality
A21: TID1600 | C21: > | D21: HAS ACQ CONTEXT | E21: UIDREF | F21: EV (ddd011, DCM, “Study Instance UID”) | G21: 1 | H21: R+ | M21: | | N21: ="SR-"&A21&":"&B21&F21 -> SR-TID1600:EV (ddd011, DCM, “Study Instance UID”) | O21: | | P21: =T(W21) -> ImagingStudy.identifier[studyInstanceUid] | Q21: | | R21: =T(Y21) -> EHDSImagingStudy- header.identifier | S21: | | V21: ImagingStudy3 | W21: =_xlfn.XLOOKUP(V21,FHIR!A:A,FHIR!E:E) -> ImagingStudy.identifier[studyInstanceUid] | X21: =IF(LEN(V21)>0,_xlfn.XLOOKUP(V21,FHIR!A:A,FHIR!M:M,""),"") -> EHDSImagingStudy4 | Y21: =_xlfn.XLOOKUP(X21,XtEHR!A:A,XtEHR!I:I,"") -> EHDSImagingStudy- header.identifier
A22: TID1600 | C22: > | D22: HAS ACQ CONTEXT | E22: CODE | F22: EV (123014, DCM, "Target Region") | G22: 1-n | H22: R+ | J22: Each content item shall correspond to the TEXT content item below of the same rank. | K22: Code value for target region selected. See 4.3.X.4.1 CID IHE-MADO1 High-Level Anatomic Regions and systems (See Note below). | M22: | | N22: ="SR-"&A22&":"&B22&F22 -> SR-TID1600:EV (123014, DCM, "Target Region") | O22: | | P22: =T(W22) -> ImagingStudy.extension[anatomical] | Q22: | | R22: =T(Y22) -> EHDSImagingStudy- bodySite | S22: | | V22: ImagingStudy7 | W22: =_xlfn.XLOOKUP(V22,FHIR!A:A,FHIR!E:E) -> ImagingStudy.extension[anatomical] | X22: =IF(LEN(V22)>0,_xlfn.XLOOKUP(V22,FHIR!A:A,FHIR!M:M,""),"") -> EHDSImagingStudy12 | Y22: =_xlfn.XLOOKUP(X22,XtEHR!A:A,XtEHR!I:I,"") -> EHDSImagingStudy- bodySite
A23: TID1600 | C23: > | D23: HAS ACQ CONTEXT | E23: TEXT | F23: EV (123014, DCM, "Target Region") | G23: 1-n | H23: R+ | J23: Each content item shall correspond to the TEXT content item above of the same rank. | K23: Text value for target region selected. See 4.3.X.4.1 CID IHE-MADO1 High-Level Anatomic Regions and systems (See Note below) | M23: | | N23: ="SR-"&A23&":"&B23&F23 -> SR-TID1600:EV (123014, DCM, "Target Region") | O23: | | P23: =T(W23) -> ImagingStudy.extension[anatomical].text | Q23: | | R23: =T(Y23) -> EHDSImagingStudy- bodySite | S23: | | V23: ImagingStudy7a | W23: =_xlfn.XLOOKUP(V23,FHIR!A:A,FHIR!E:E) -> ImagingStudy.extension[anatomical].text | X23: =IF(LEN(V23)>0,_xlfn.XLOOKUP(V23,FHIR!A:A,FHIR!M:M,""),"") -> EHDSImagingStudy12 | Y23: =_xlfn.XLOOKUP(X23,XtEHR!A:A,XtEHR!I:I,"") -> EHDSImagingStudy- bodySite
A24: TID1600 | C24: > | D24: HAS ACQ CONTEXT | E24: NUM or TEXT ? | F24: EV (ddd010, DCM, “Number of Study Related Series” | G24: 1 | H24: U | K24: ? UNITS = EV ({instances}, UCUM, "instances") | M24: | | N24: ="SR-"&A24&":"&B24&F24 -> SR-TID1600:EV (ddd010, DCM, “Number of Study Related Series” | O24: | | P24: =T(W24) -> ImagingStudy.series | Q24: | | R24: =T(Y24) -> EHDSImagingStudy- series | S24: | | V24: ImagingStudy24 | W24: =_xlfn.XLOOKUP(V24,FHIR!A:A,FHIR!E:E) -> ImagingStudy.series | X24: =IF(LEN(V24)>0,_xlfn.XLOOKUP(V24,FHIR!A:A,FHIR!M:M,""),"") -> EHDSImagingStudy21 | Y24: =_xlfn.XLOOKUP(X24,XtEHR!A:A,XtEHR!I:I,"") -> EHDSImagingStudy- series
D25: question: does this attribute reflect the number of series in the original study the manifest is based on. Or does it list the amount of series that are referenced by this manifest? | M25: | | N25: ="SR-"&A25&":"&B25&F25 -> SR-: | O25: | | P25: =T(W25) -> -------- | Q25: | | R25: =T(Y25) | S25: | | W25: =_xlfn.XLOOKUP(V25,FHIR!A:A,FHIR!E:E) -> -------- | X25: =IF(LEN(V25)>0,_xlfn.XLOOKUP(V25,FHIR!A:A,FHIR!M:M,""),"") | Y25: =_xlfn.XLOOKUP(X25,XtEHR!A:A,XtEHR!I:I,"")
M26: | | N26: ="SR-"&A26&":"&B26&F26 -> SR-: | O26: | | P26: =T(W26) -> -------- | Q26: | | R26: =T(Y26) | S26: | | W26: =_xlfn.XLOOKUP(V26,FHIR!A:A,FHIR!E:E) -> -------- | X26: =IF(LEN(V26)>0,_xlfn.XLOOKUP(V26,FHIR!A:A,FHIR!M:M,""),"") | Y26: =_xlfn.XLOOKUP(X26,XtEHR!A:A,XtEHR!I:I,"")
A27: TID1601 | B27: NL | C27: Rel with Parent | D27: VT | E27: Concept Name | F27: VM | G27: Req Type | H27: Condition | J27: Value Set Constraint | M27: | | N27: ="SR-"&A27&":"&B27&F27 -> SR-TID1601:NLVM | O27: | | P27: =T(W27) -> -------- | Q27: | | R27: =T(Y27) | S27: | | W27: =_xlfn.XLOOKUP(V27,FHIR!A:A,FHIR!E:E) -> -------- | X27: =IF(LEN(V27)>0,_xlfn.XLOOKUP(V27,FHIR!A:A,FHIR!M:M,""),"") | Y27: =_xlfn.XLOOKUP(X27,XtEHR!A:A,XtEHR!I:I,"")
A28: TID1601 | B28: 1 | E28: IMAGE | G28: 1 | H28: M | M28: | | N28: ="SR-"&A28&":"&B28&F28 -> SR-TID1601:1 | O28: | | P28: =T(W28) -> -------- | Q28: | | R28: =T(Y28) | S28: | | W28: =_xlfn.XLOOKUP(V28,FHIR!A:A,FHIR!E:E) -> -------- | X28: =IF(LEN(V28)>0,_xlfn.XLOOKUP(V28,FHIR!A:A,FHIR!M:M,""),"") | Y28: =_xlfn.XLOOKUP(X28,XtEHR!A:A,XtEHR!I:I,"")
A29: TID1601 | B29: 2 | C29: > | D29: HAS ACQ CONTEXT | E29: INCLUDE | F29: DTID 1602 “Image Library Entry Descriptors” | G29: 1 | H29: U | M29: | | N29: ="SR-"&A29&":"&B29&F29 -> SR-TID1601:2DTID 1602 “Image Library Entry Descriptors” | O29: | | P29: =T(W29) -> -------- | Q29: | | R29: =T(Y29) | S29: | | W29: =_xlfn.XLOOKUP(V29,FHIR!A:A,FHIR!E:E) -> -------- | X29: =IF(LEN(V29)>0,_xlfn.XLOOKUP(V29,FHIR!A:A,FHIR!M:M,""),"") | Y29: =_xlfn.XLOOKUP(X29,XtEHR!A:A,XtEHR!I:I,"")
